<?xml version="1.0" encoding="UTF-8"?>
<testng-results skipped="2" failed="1" ignored="0" total="3" passed="0">
  <reporter-output>
  </reporter-output>
  <suite name="Default suite" duration-ms="115" started-at="2019-01-31T14:23:01Z" finished-at="2019-01-31T14:23:01Z">
    <groups>
    </groups>
    <test name="Default test" duration-ms="115" started-at="2019-01-31T14:23:01Z" finished-at="2019-01-31T14:23:01Z">
      <class name="firsttestng.myapp">
        <test-method status="FAIL" signature="startapp()[pri:0, instance:firsttestng.myapp@2ef5e5e3]" name="startapp" duration-ms="30" started-at="2019-01-31T14:23:01Z" finished-at="2019-01-31T14:23:01Z">
          <exception class="java.lang.AssertionError">
            <message>
              <![CDATA[expected [13] but found [12]]]>
            </message>
            <full-stacktrace>
              <![CDATA[java.lang.AssertionError: expected [13] but found [12]
at org.testng.Assert.fail(Assert.java:96)
at org.testng.Assert.failNotEquals(Assert.java:776)
at org.testng.Assert.assertEqualsImpl(Assert.java:137)
at org.testng.Assert.assertEquals(Assert.java:118)
at org.testng.Assert.assertEquals(Assert.java:652)
at org.testng.Assert.assertEquals(Assert.java:662)
at firsttestng.myapp.startapp(myapp.java:12)
at sun.reflect.NativeMethodAccessorImpl.invoke0(Native Method)
at sun.reflect.NativeMethodAccessorImpl.invoke(Unknown Source)
at sun.reflect.DelegatingMethodAccessorImpl.invoke(Unknown Source)
at java.lang.reflect.Method.invoke(Unknown Source)
at org.testng.internal.MethodInvocationHelper.invokeMethod(MethodInvocationHelper.java:124)
at org.testng.internal.Invoker.invokeMethod(Invoker.java:580)
at org.testng.internal.Invoker.invokeTestMethod(Invoker.java:716)
at org.testng.internal.Invoker.invokeTestMethods(Invoker.java:988)
at org.testng.internal.TestMethodWorker.invokeTestMethods(TestMethodWorker.java:125)
at org.testng.internal.TestMethodWorker.run(TestMethodWorker.java:109)
at org.testng.TestRunner.privateRun(TestRunner.java:648)
at org.testng.TestRunner.run(TestRunner.java:505)
at org.testng.SuiteRunner.runTest(SuiteRunner.java:455)
at org.testng.SuiteRunner.runSequentially(SuiteRunner.java:450)
at org.testng.SuiteRunner.privateRun(SuiteRunner.java:415)
at org.testng.SuiteRunner.run(SuiteRunner.java:364)
at org.testng.SuiteRunnerWorker.runSuite(SuiteRunnerWorker.java:52)
at org.testng.SuiteRunnerWorker.run(SuiteRunnerWorker.java:84)
at org.testng.TestNG.runSuitesSequentially(TestNG.java:1208)
at org.testng.TestNG.runSuitesLocally(TestNG.java:1137)
at org.testng.TestNG.runSuites(TestNG.java:1049)
at org.testng.TestNG.run(TestNG.java:1017)
at org.testng.remote.AbstractRemoteTestNG.run(AbstractRemoteTestNG.java:114)
at org.testng.remote.RemoteTestNG.initAndRun(RemoteTestNG.java:251)
at org.testng.remote.RemoteTestNG.main(RemoteTestNG.java:77)
]]>
            </full-stacktrace>
          </exception> <!-- java.lang.AssertionError -->
          <reporter-output>
          </reporter-output>
        </test-method> <!-- startapp -->
        <test-method status="SKIP" signature="loginapp()[pri:0, instance:firsttestng.myapp@2ef5e5e3]" name="loginapp" duration-ms="0" started-at="2019-01-31T14:23:01Z" depends-on-methods="firsttestng.myapp.startapp" finished-at="2019-01-31T14:23:01Z">
          <exception class="java.lang.Throwable">
            <message>
              <![CDATA[Method myapp.loginapp()[pri:0, instance:firsttestng.myapp@2ef5e5e3] depends on not successfully finished methods]]>
            </message>
            <full-stacktrace>
              <![CDATA[java.lang.Throwable: Method myapp.loginapp()[pri:0, instance:firsttestng.myapp@2ef5e5e3] depends on not successfully finished methods
at org.testng.internal.Invoker.invokeTestMethods(Invoker.java:887)
at org.testng.internal.TestMethodWorker.invokeTestMethods(TestMethodWorker.java:125)
at org.testng.internal.TestMethodWorker.run(TestMethodWorker.java:109)
at org.testng.TestRunner.privateRun(TestRunner.java:648)
at org.testng.TestRunner.run(TestRunner.java:505)
at org.testng.SuiteRunner.runTest(SuiteRunner.java:455)
at org.testng.SuiteRunner.runSequentially(SuiteRunner.java:450)
at org.testng.SuiteRunner.privateRun(SuiteRunner.java:415)
at org.testng.SuiteRunner.run(SuiteRunner.java:364)
at org.testng.SuiteRunnerWorker.runSuite(SuiteRunnerWorker.java:52)
at org.testng.SuiteRunnerWorker.run(SuiteRunnerWorker.java:84)
at org.testng.TestNG.runSuitesSequentially(TestNG.java:1208)
at org.testng.TestNG.runSuitesLocally(TestNG.java:1137)
at org.testng.TestNG.runSuites(TestNG.java:1049)
at org.testng.TestNG.run(TestNG.java:1017)
at org.testng.remote.AbstractRemoteTestNG.run(AbstractRemoteTestNG.java:114)
at org.testng.remote.RemoteTestNG.initAndRun(RemoteTestNG.java:251)
at org.testng.remote.RemoteTestNG.main(RemoteTestNG.java:77)
]]>
            </full-stacktrace>
          </exception> <!-- java.lang.Throwable -->
          <reporter-output>
          </reporter-output>
        </test-method> <!-- loginapp -->
        <test-method status="SKIP" signature="logoutapp()[pri:0, instance:firsttestng.myapp@2ef5e5e3]" name="logoutapp" duration-ms="0" started-at="2019-01-31T14:23:01Z" depends-on-methods="firsttestng.myapp.loginapp" finished-at="2019-01-31T14:23:01Z">
          <exception class="java.lang.Throwable">
            <message>
              <![CDATA[Method myapp.logoutapp()[pri:0, instance:firsttestng.myapp@2ef5e5e3] depends on not successfully finished methods]]>
            </message>
            <full-stacktrace>
              <![CDATA[java.lang.Throwable: Method myapp.logoutapp()[pri:0, instance:firsttestng.myapp@2ef5e5e3] depends on not successfully finished methods
at org.testng.internal.Invoker.invokeTestMethods(Invoker.java:887)
at org.testng.internal.TestMethodWorker.invokeTestMethods(TestMethodWorker.java:125)
at org.testng.internal.TestMethodWorker.run(TestMethodWorker.java:109)
at org.testng.TestRunner.privateRun(TestRunner.java:648)
at org.testng.TestRunner.run(TestRunner.java:505)
at org.testng.SuiteRunner.runTest(SuiteRunner.java:455)
at org.testng.SuiteRunner.runSequentially(SuiteRunner.java:450)
at org.testng.SuiteRunner.privateRun(SuiteRunner.java:415)
at org.testng.SuiteRunner.run(SuiteRunner.java:364)
at org.testng.SuiteRunnerWorker.runSuite(SuiteRunnerWorker.java:52)
at org.testng.SuiteRunnerWorker.run(SuiteRunnerWorker.java:84)
at org.testng.TestNG.runSuitesSequentially(TestNG.java:1208)
at org.testng.TestNG.runSuitesLocally(TestNG.java:1137)
at org.testng.TestNG.runSuites(TestNG.java:1049)
at org.testng.TestNG.run(TestNG.java:1017)
at org.testng.remote.AbstractRemoteTestNG.run(AbstractRemoteTestNG.java:114)
at org.testng.remote.RemoteTestNG.initAndRun(RemoteTestNG.java:251)
at org.testng.remote.RemoteTestNG.main(RemoteTestNG.java:77)
]]>
            </full-stacktrace>
          </exception> <!-- java.lang.Throwable -->
          <reporter-output>
          </reporter-output>
        </test-method> <!-- logoutapp -->
      </class> <!-- firsttestng.myapp -->
    </test> <!-- Default test -->
  </suite> <!-- Default suite -->
</testng-results>
